
2024-03-02 18:31:59 | ERROR | Logger.add_to_log() takes 3 positional arguments but 4 were given
2024-03-02 18:31:59 | ERROR | Traceback (most recent call last):
  File "C:\Users\jeiso\Documents\TrabajoUdeA\consolidado\backend\venv\Lib\site-packages\sqlalchemy\engine\base.py", line 1960, in _exec_single_context
    self.dialect.do_execute(
  File "C:\Users\jeiso\Documents\TrabajoUdeA\consolidado\backend\venv\Lib\site-packages\sqlalchemy\engine\default.py", line 924, in do_execute
    cursor.execute(statement, parameters)
psycopg2.errors.UndefinedColumn: column users.password does not exist
LINE 1: ...s.name AS users_name, users.email AS users_email, users.pass...
                                                             ^


The above exception was the direct cause of the following exception:

Traceback (most recent call last):
  File "C:\Users\jeiso\Documents\TrabajoUdeA\consolidado\backend\app\services\auth\signup_service.py", line 18, in signup
    user = User.query.filter_by(email=self.email).first()
           ^^^^^^^^^^^^^^^^^^^^^^^^^^^^^^^^^^^^^^^^^^^^^^
  File "C:\Users\jeiso\Documents\TrabajoUdeA\consolidado\backend\venv\Lib\site-packages\sqlalchemy\orm\query.py", line 2727, in first
    return self.limit(1)._iter().first()  # type: ignore
           ^^^^^^^^^^^^^^^^^^^^^
  File "C:\Users\jeiso\Documents\TrabajoUdeA\consolidado\backend\venv\Lib\site-packages\sqlalchemy\orm\query.py", line 2826, in _iter
    result: Union[ScalarResult[_T], Result[_T]] = self.session.execute(
                                                  ^^^^^^^^^^^^^^^^^^^^^
  File "C:\Users\jeiso\Documents\TrabajoUdeA\consolidado\backend\venv\Lib\site-packages\sqlalchemy\orm\session.py", line 2306, in execute
    return self._execute_internal(
           ^^^^^^^^^^^^^^^^^^^^^^^
  File "C:\Users\jeiso\Documents\TrabajoUdeA\consolidado\backend\venv\Lib\site-packages\sqlalchemy\orm\session.py", line 2191, in _execute_internal
    result: Result[Any] = compile_state_cls.orm_execute_statement(
                          ^^^^^^^^^^^^^^^^^^^^^^^^^^^^^^^^^^^^^^^^
  File "C:\Users\jeiso\Documents\TrabajoUdeA\consolidado\backend\venv\Lib\site-packages\sqlalchemy\orm\context.py", line 293, in orm_execute_statement
    result = conn.execute(
             ^^^^^^^^^^^^^
  File "C:\Users\jeiso\Documents\TrabajoUdeA\consolidado\backend\venv\Lib\site-packages\sqlalchemy\engine\base.py", line 1408, in execute
    return meth(
           ^^^^^
  File "C:\Users\jeiso\Documents\TrabajoUdeA\consolidado\backend\venv\Lib\site-packages\sqlalchemy\sql\elements.py", line 513, in _execute_on_connection
    return connection._execute_clauseelement(
           ^^^^^^^^^^^^^^^^^^^^^^^^^^^^^^^^^^
  File "C:\Users\jeiso\Documents\TrabajoUdeA\consolidado\backend\venv\Lib\site-packages\sqlalchemy\engine\base.py", line 1630, in _execute_clauseelement
    ret = self._execute_context(
          ^^^^^^^^^^^^^^^^^^^^^^
  File "C:\Users\jeiso\Documents\TrabajoUdeA\consolidado\backend\venv\Lib\site-packages\sqlalchemy\engine\base.py", line 1839, in _execute_context
    return self._exec_single_context(
           ^^^^^^^^^^^^^^^^^^^^^^^^^^
  File "C:\Users\jeiso\Documents\TrabajoUdeA\consolidado\backend\venv\Lib\site-packages\sqlalchemy\engine\base.py", line 1979, in _exec_single_context
    self._handle_dbapi_exception(
  File "C:\Users\jeiso\Documents\TrabajoUdeA\consolidado\backend\venv\Lib\site-packages\sqlalchemy\engine\base.py", line 2335, in _handle_dbapi_exception
    raise sqlalchemy_exception.with_traceback(exc_info[2]) from e
  File "C:\Users\jeiso\Documents\TrabajoUdeA\consolidado\backend\venv\Lib\site-packages\sqlalchemy\engine\base.py", line 1960, in _exec_single_context
    self.dialect.do_execute(
  File "C:\Users\jeiso\Documents\TrabajoUdeA\consolidado\backend\venv\Lib\site-packages\sqlalchemy\engine\default.py", line 924, in do_execute
    cursor.execute(statement, parameters)
sqlalchemy.exc.ProgrammingError: (psycopg2.errors.UndefinedColumn) column users.password does not exist
LINE 1: ...s.name AS users_name, users.email AS users_email, users.pass...
                                                             ^

[SQL: SELECT users.id AS users_id, users.name AS users_name, users.email AS users_email, users.password AS users_password, users.email_verified AS users_email_verified, users.image AS users_image, users.created_at AS users_created_at, users.updated_at AS users_updated_at, users.deleted_at AS users_deleted_at 
FROM users 
WHERE users.email = %(email_1)s 
 LIMIT %(param_1)s]
[parameters: {'email_1': 'test1@mail.com', 'param_1': 1}]
(Background on this error at: https://sqlalche.me/e/20/f405)

During handling of the above exception, another exception occurred:

Traceback (most recent call last):
  File "C:\Users\jeiso\Documents\TrabajoUdeA\consolidado\backend\app\routes\auth_routes.py", line 17, in signup
    return SignupService(name, email, password, verify_password, image).signup()
           ^^^^^^^^^^^^^^^^^^^^^^^^^^^^^^^^^^^^^^^^^^^^^^^^^^^^^^^^^^^^^^^^^^^^^
  File "C:\Users\jeiso\Documents\TrabajoUdeA\consolidado\backend\app\services\auth\signup_service.py", line 34, in signup
    Logger.add_to_log('error', 'signup_service', str(e))
TypeError: Logger.add_to_log() takes 3 positional arguments but 4 were given

2024-03-02 18:33:03 | ERROR | (psycopg2.errors.UndefinedColumn) column users.password does not exist
LINE 1: ...s.name AS users_name, users.email AS users_email, users.pass...
                                                             ^

[SQL: SELECT users.id AS users_id, users.name AS users_name, users.email AS users_email, users.password AS users_password, users.email_verified AS users_email_verified, users.image AS users_image, users.created_at AS users_created_at, users.updated_at AS users_updated_at, users.deleted_at AS users_deleted_at 
FROM users 
WHERE users.email = %(email_1)s 
 LIMIT %(param_1)s]
[parameters: {'email_1': 'test1@mail.com', 'param_1': 1}]
(Background on this error at: https://sqlalche.me/e/20/f405)
2024-03-02 18:33:03 | ERROR | Traceback (most recent call last):
  File "C:\Users\jeiso\Documents\TrabajoUdeA\consolidado\backend\venv\Lib\site-packages\sqlalchemy\engine\base.py", line 1960, in _exec_single_context
    self.dialect.do_execute(
  File "C:\Users\jeiso\Documents\TrabajoUdeA\consolidado\backend\venv\Lib\site-packages\sqlalchemy\engine\default.py", line 924, in do_execute
    cursor.execute(statement, parameters)
psycopg2.errors.UndefinedColumn: column users.password does not exist
LINE 1: ...s.name AS users_name, users.email AS users_email, users.pass...
                                                             ^


The above exception was the direct cause of the following exception:

Traceback (most recent call last):
  File "C:\Users\jeiso\Documents\TrabajoUdeA\consolidado\backend\app\services\auth\signup_service.py", line 18, in signup
    user = User.query.filter_by(email=self.email).first()
           ^^^^^^^^^^^^^^^^^^^^^^^^^^^^^^^^^^^^^^^^^^^^^^
  File "C:\Users\jeiso\Documents\TrabajoUdeA\consolidado\backend\venv\Lib\site-packages\sqlalchemy\orm\query.py", line 2727, in first
    return self.limit(1)._iter().first()  # type: ignore
           ^^^^^^^^^^^^^^^^^^^^^
  File "C:\Users\jeiso\Documents\TrabajoUdeA\consolidado\backend\venv\Lib\site-packages\sqlalchemy\orm\query.py", line 2826, in _iter
    result: Union[ScalarResult[_T], Result[_T]] = self.session.execute(
                                                  ^^^^^^^^^^^^^^^^^^^^^
  File "C:\Users\jeiso\Documents\TrabajoUdeA\consolidado\backend\venv\Lib\site-packages\sqlalchemy\orm\session.py", line 2306, in execute
    return self._execute_internal(
           ^^^^^^^^^^^^^^^^^^^^^^^
  File "C:\Users\jeiso\Documents\TrabajoUdeA\consolidado\backend\venv\Lib\site-packages\sqlalchemy\orm\session.py", line 2191, in _execute_internal
    result: Result[Any] = compile_state_cls.orm_execute_statement(
                          ^^^^^^^^^^^^^^^^^^^^^^^^^^^^^^^^^^^^^^^^
  File "C:\Users\jeiso\Documents\TrabajoUdeA\consolidado\backend\venv\Lib\site-packages\sqlalchemy\orm\context.py", line 293, in orm_execute_statement
    result = conn.execute(
             ^^^^^^^^^^^^^
  File "C:\Users\jeiso\Documents\TrabajoUdeA\consolidado\backend\venv\Lib\site-packages\sqlalchemy\engine\base.py", line 1408, in execute
    return meth(
           ^^^^^
  File "C:\Users\jeiso\Documents\TrabajoUdeA\consolidado\backend\venv\Lib\site-packages\sqlalchemy\sql\elements.py", line 513, in _execute_on_connection
    return connection._execute_clauseelement(
           ^^^^^^^^^^^^^^^^^^^^^^^^^^^^^^^^^^
  File "C:\Users\jeiso\Documents\TrabajoUdeA\consolidado\backend\venv\Lib\site-packages\sqlalchemy\engine\base.py", line 1630, in _execute_clauseelement
    ret = self._execute_context(
          ^^^^^^^^^^^^^^^^^^^^^^
  File "C:\Users\jeiso\Documents\TrabajoUdeA\consolidado\backend\venv\Lib\site-packages\sqlalchemy\engine\base.py", line 1839, in _execute_context
    return self._exec_single_context(
           ^^^^^^^^^^^^^^^^^^^^^^^^^^
  File "C:\Users\jeiso\Documents\TrabajoUdeA\consolidado\backend\venv\Lib\site-packages\sqlalchemy\engine\base.py", line 1979, in _exec_single_context
    self._handle_dbapi_exception(
  File "C:\Users\jeiso\Documents\TrabajoUdeA\consolidado\backend\venv\Lib\site-packages\sqlalchemy\engine\base.py", line 2335, in _handle_dbapi_exception
    raise sqlalchemy_exception.with_traceback(exc_info[2]) from e
  File "C:\Users\jeiso\Documents\TrabajoUdeA\consolidado\backend\venv\Lib\site-packages\sqlalchemy\engine\base.py", line 1960, in _exec_single_context
    self.dialect.do_execute(
  File "C:\Users\jeiso\Documents\TrabajoUdeA\consolidado\backend\venv\Lib\site-packages\sqlalchemy\engine\default.py", line 924, in do_execute
    cursor.execute(statement, parameters)
sqlalchemy.exc.ProgrammingError: (psycopg2.errors.UndefinedColumn) column users.password does not exist
LINE 1: ...s.name AS users_name, users.email AS users_email, users.pass...
                                                             ^

[SQL: SELECT users.id AS users_id, users.name AS users_name, users.email AS users_email, users.password AS users_password, users.email_verified AS users_email_verified, users.image AS users_image, users.created_at AS users_created_at, users.updated_at AS users_updated_at, users.deleted_at AS users_deleted_at 
FROM users 
WHERE users.email = %(email_1)s 
 LIMIT %(param_1)s]
[parameters: {'email_1': 'test1@mail.com', 'param_1': 1}]
(Background on this error at: https://sqlalche.me/e/20/f405)

